Workbook
Name Slicer_RegionName: #N/A

Sheet dash board
A1: E-Commerce Sales Dashboard
C3: Total Orders | F3: Total Revenue | J3: Total profit | N3: Profit Margin
C4: =COUNTA(Orders!A:A)-1 -> 3000 | F4: =SUM(Orders!L:L) -> 5047627.2 | J4: =SUM(Sales!K:K) -> 2333641.8 | N4: =J4/F4 -> 0.46232452

Sheet Categories
A1: CategoryID | B1: CategoryName
A2: 1 | B2: Electronics
A3: 2 | B3: Apparel
A4: 3 | B4: Home & Kitchen
A5: 4 | B5: Beauty & Personal Care
A6: 5 | B6: Sports & Outdoors
A7: 6 | B7: Books & Stationery
A8: 7 | B8: Toys & Games
A9: 8 | B9: Grocery

Sheet Regions
A1: RegionID | B1: RegionName | C1: Country
A2: 1 | B2: North | C2: India
A3: 2 | B3: South | C3: India
A4: 3 | B4: East | C4: India
A5: 4 | B5: West | C5: India
A6: 5 | B6: Central | C6: India

Sheet Products
A1: ProductID | B1: ProductName | C1: CategoryID | D1: Cost | E1: ListPrice | F1: CategoryName | G1: TotalUnitsSold | H1: TotalRevenue | I1: TotalProfit | J1: ReturnCount
A2: 1001 | B2: Wireless Earbuds | C2: 1 | D2: 3021.65 | E2: 3826.19 | F2: =IFERROR(INDEX(Categories!$B$2:$B$9,MATCH(C2,Categories!$A$2:$A$9,0)),"") -> Electronics | G2: =SUMIFS(Sales!$D$2:$D$4584,Sales!$C$2:$C$4584,A2) -> 402 | H2: =SUMIFS(Sales!$I$2:$I$4584,Sales!$C$2:$C$4584,A2) -> 1375897.9 | I2: =SUMIFS(Sales!$K$2:$K$4584,Sales!$C$2:$C$4584,A2) -> 161194.62 | J2: =SUMPRODUCT((Sales!$C$2:$C$4584=A2)*(Sales!$M$2:$M$4584="Yes")) -> 29
A3: 1002 | B3: Bluetooth Speaker | C3: 1 | D3: 1527.62 | E3: 2131.16 | F3: =IFERROR(INDEX(Categories!$B$2:$B$9,MATCH(C3,Categories!$A$2:$A$9,0)),"") -> Electronics | G3: =SUMIFS(Sales!$D$2:$D$4584,Sales!$C$2:$C$4584,A3) -> 15 | H3: =SUMIFS(Sales!$I$2:$I$4584,Sales!$C$2:$C$4584,A3) -> 26532.942 | I3: =SUMIFS(Sales!$K$2:$K$4584,Sales!$C$2:$C$4584,A3) -> 3618.642 | J3: =SUMPRODUCT((Sales!$C$2:$C$4584=A3)*(Sales!$M$2:$M$4584="Yes")) -> 2
A4: 1003 | B4: Smartwatch | C4: 1 | D4: 3419.53 | E4: 5778.51 | F4: =IFERROR(INDEX(Categories!$B$2:$B$9,MATCH(C4,Categories!$A$2:$A$9,0)),"") -> Electronics | G4: =SUMIFS(Sales!$D$2:$D$4584,Sales!$C$2:$C$4584,A4) -> 26 | H4: =SUMIFS(Sales!$I$2:$I$4584,Sales!$C$2:$C$4584,A4) -> 131750.03 | I4: =SUMIFS(Sales!$K$2:$K$4584,Sales!$C$2:$C$4584,A4) -> 42842.248 | J4: =SUMPRODUCT((Sales!$C$2:$C$4584=A4)*(Sales!$M$2:$M$4584="Yes")) -> 1
A5: 1004 | B5: Power Bank 10000mAh | C5: 1 | D5: 4057.94 | E5: 5301.74 | F5: =IFERROR(INDEX(Categories!$B$2:$B$9,MATCH(C5,Categories!$A$2:$A$9,0)),"") -> Electronics | G5: =SUMIFS(Sales!$D$2:$D$4584,Sales!$C$2:$C$4584,A5) -> 15 | H5: =SUMIFS(Sales!$I$2:$I$4584,Sales!$C$2:$C$4584,A5) -> 66006.663 | I5: =SUMIFS(Sales!$K$2:$K$4584,Sales!$C$2:$C$4584,A5) -> 5137.563 | J5: =SUMPRODUCT((Sales!$C$2:$C$4584=A5)*(Sales!$M$2:$M$4584="Yes")) -> 2
A6: 1005 | B6: USB-C Charger | C6: 1 | D6: 2129.88 | E6: 2703.6 | F6: =IFERROR(INDEX(Categories!$B$2:$B$9,MATCH(C6,Categories!$A$2:$A$9,0)),"") -> Electronics | G6: =SUMIFS(Sales!$D$2:$D$4584,Sales!$C$2:$C$4584,A6) -> 102 | H6: =SUMIFS(Sales!$I$2:$I$4584,Sales!$C$2:$C$4584,A6) -> 247244.22 | I6: =SUMIFS(Sales!$K$2:$K$4584,Sales!$C$2:$C$4584,A6) -> 29996.46 | J6: =SUMPRODUCT((Sales!$C$2:$C$4584=A6)*(Sales!$M$2:$M$4584="Yes")) -> 11
A7: 1006 | B7: Laptop Stand | C7: 1 | D7: 1296.42 | E7: 2046.37 | F7: =IFERROR(INDEX(Categories!$B$2:$B$9,MATCH(C7,Categories!$A$2:$A$9,0)),"") -> Electronics | G7: =SUMIFS(Sales!$D$2:$D$4584,Sales!$C$2:$C$4584,A7) -> 135 | H7: =SUMIFS(Sales!$I$2:$I$4584,Sales!$C$2:$C$4584,A7) -> 245666.72 | I7: =SUMIFS(Sales!$K$2:$K$4584,Sales!$C$2:$C$4584,A7) -> 70650.018 | J7: =SUMPRODUCT((Sales!$C$2:$C$4584=A7)*(Sales!$M$2:$M$4584="Yes")) -> 10
A8: 1007 | B8: Wireless Mouse | C8: 1 | D8: 508.8 | E8: 701.76 | F8: =IFERROR(INDEX(Categories!$B$2:$B$9,MATCH(C8,Categories!$A$2:$A$9,0)),"") -> Electronics | G8: =SUMIFS(Sales!$D$2:$D$4584,Sales!$C$2:$C$4584,A8) -> 51 | H8: =SUMIFS(Sales!$I$2:$I$4584,Sales!$C$2:$C$4584,A8) -> 31719.552 | I8: =SUMIFS(Sales!$K$2:$K$4584,Sales!$C$2:$C$4584,A8) -> 5770.752 | J8: =SUMPRODUCT((Sales!$C$2:$C$4584=A8)*(Sales!$M$2:$M$4584="Yes")) -> 2
A9: 1008 | B9: Mechanical Keyboard | C9: 1 | D9: 3064.53 | E9: 4916.16 | F9: =IFERROR(INDEX(Categories!$B$2:$B$9,MATCH(C9,Categories!$A$2:$A$9,0)),"") -> Electronics | G9: =SUMIFS(Sales!$D$2:$D$4584,Sales!$C$2:$C$4584,A9) -> 11 | H9: =SUMIFS(Sales!$I$2:$I$4584,Sales!$C$2:$C$4584,A9) -> 45720.288 | I9: =SUMIFS(Sales!$K$2:$K$4584,Sales!$C$2:$C$4584,A9) -> 12010.458 | J9: =SUMPRODUCT((Sales!$C$2:$C$4584=A9)*(Sales!$M$2:$M$4584="Yes")) -> 1
A10: 1009 | B10: Webcam HD | C10: 1 | D10: 1303.81 | E10: 2129.15 | F10: =IFERROR(INDEX(Categories!$B$2:$B$9,MATCH(C10,Categories!$A$2:$A$9,0)),"") -> Electronics | G10: =SUMIFS(Sales!$D$2:$D$4584,Sales!$C$2:$C$4584,A10) -> 56 | H10: =SUMIFS(Sales!$I$2:$I$4584,Sales!$C$2:$C$4584,A10) -> 107202.7 | I10: =SUMIFS(Sales!$K$2:$K$4584,Sales!$C$2:$C$4584,A10) -> 34189.343 | J10: =SUMPRODUCT((Sales!$C$2:$C$4584=A10)*(Sales!$M$2:$M$4584="Yes")) -> 7
A11: 1010 | B11: Phone Case | C11: 1 | D11: 3718.66 | E11: 4664.03 | F11: =IFERROR(INDEX(Categories!$B$2:$B$9,MATCH(C11,Categories!$A$2:$A$9,0)),"") -> Electronics | G11: =SUMIFS(Sales!$D$2:$D$4584,Sales!$C$2:$C$4584,A11) -> 30 | H11: =SUMIFS(Sales!$I$2:$I$4584,Sales!$C$2:$C$4584,A11) -> 119865.57 | I11: =SUMIFS(Sales!$K$2:$K$4584,Sales!$C$2:$C$4584,A11) -> 8305.771 | J11: =SUMPRODUCT((Sales!$C$2:$C$4584=A11)*(Sales!$M$2:$M$4584="Yes")) -> 3
A12: 1011 | B12: Screen Protector | C12: 1 | D12: 3703.86 | E12: 6310.6 | F12: =IFERROR(INDEX(Categories!$B$2:$B$9,MATCH(C12,Categories!$A$2:$A$9,0)),"") -> Electronics | G12: =SUMIFS(Sales!$D$2:$D$4584,Sales!$C$2:$C$4584,A12) -> 29 | H12: =SUMIFS(Sales!$I$2:$I$4584,Sales!$C$2:$C$4584,A12) -> 171017.26 | I12: =SUMIFS(Sales!$K$2:$K$4584,Sales!$C$2:$C$4584,A12) -> 63605.32 | J12: =SUMPRODUCT((Sales!$C$2:$C$4584=A12)*(Sales!$M$2:$M$4584="Yes")) -> 2
A13: 1012 | B13: Portable SSD 500GB | C13: 1 | D13: 1795.03 | E13: 2425.2 | F13: =IFERROR(INDEX(Categories!$B$2:$B$9,MATCH(C13,Categories!$A$2:$A$9,0)),"") -> Electronics | G13: =SUMIFS(Sales!$D$2:$D$4584,Sales!$C$2:$C$4584,A13) -> 32 | H13: =SUMIFS(Sales!$I$2:$I$4584,Sales!$C$2:$C$4584,A13) -> 66450.48 | I13: =SUMIFS(Sales!$K$2:$K$4584,Sales!$C$2:$C$4584,A13) -> 9009.52 | J13: =SUMPRODUCT((Sales!$C$2:$C$4584=A13)*(Sales!$M$2:$M$4584="Yes")) -> 3
... A86: 1085 | B86: Spice Combo Pack | C86: 8 | D86: 175.69 | E86: 234.72 | F86: =IFERROR(INDEX(Categories!$B$2:$B$9,MATCH(C86,Categories!$A$2:$A$9,0)),"") -> Grocery | G86: =SUMIFS(Sales!$D$2:$D$4584,Sales!$C$2:$C$4584,A86) -> 408 | H86: =SUMIFS(Sales!$I$2:$I$4584,Sales!$C$2:$C$4584,A86) -> 84651.768 | I86: =SUMIFS(Sales!$K$2:$K$4584,Sales!$C$2:$C$4584,A86) -> 12970.248 | J86: =SUMPRODUCT((Sales!$C$2:$C$4584=A86)*(Sales!$M$2:$M$4584="Yes")) -> 1

Sheet Customers
A1: CustomerID | B1: CustomerName | C1: Segment | D1: RegionID | E1: JoinDate
A2: 1 | B2: Lakshmi Joshi | C2: Consumer | D2: 4 | E2: 45343
A3: 2 | B3: Saanvi Reddy | C3: Consumer | D3: 4 | E3: 45289
A4: 3 | B4: Deepa Malhotra | C4: Consumer | D4: 1 | E4: 45616
A5: 4 | B5: Reyansh Verma | C5: Consumer | D5: 3 | E5: 45038
A6: 5 | B6: Pari Gupta | C6: Consumer | D6: 4 | E6: 45070
A7: 6 | B7: Deepa Patel | C7: Consumer | D7: 2 | E7: 45004
A8: 7 | B8: Kavya Mehta | C8: Consumer | D8: 5 | E8: 44942
A9: 8 | B9: Sai Menon | C9: Consumer | D9: 4 | E9: 45419
A10: 9 | B10: Aadhya Kapoor | C10: SMB | D10: 2 | E10: 45315
A11: 10 | B11: Aarav Kapoor | C11: Consumer | D11: 4 | E11: 45219
A12: 11 | B12: Deepa Mehta | C12: Corporate | D12: 4 | E12: 45085
A13: 12 | B13: Saanvi Rao | C13: Consumer | D13: 1 | E13: 45520
... A901: 900 | B901: Kiara Shetty | C901: Consumer | D901: 2 | E901: 45252

Sheet Sheet2
A3: Row Labels | B3: Sum of Total Revenue
A4: 2024 | B4: 466738.93
A5: Apr | B5: 29177.63
A6: May | B6: 20878.94
A7: Jun | B7: 24392.63
A8: Jul | B8: 46439.57
A9: Aug | B9: 61619.87
A10: Sep | B10: 55886.78
A11: Oct | B11: 94568.71
A12: Nov | B12: 77791.67
A13: Dec | B13: 55983.13
A14: 2025 | B14: 426080.9
A15: Jan | B15: 50370.32
... A24: Grand Total | B24: 892819.83

Sheet Sheet3
A3: Count of OrderID
A4: 530

Sheet Sheet5
A3: Row Labels | B3: Sum of Total Revenue
A4: Central | B4: 892819.83
A5: Grand Total | B5: 892819.83

Sheet Sheet10
A3: Row Labels | B3: Sum of Total Revenue
A4: Central | B4: 892819.83
A5: Grand Total | B5: 892819.83

Sheet Orders
A1: OrderID | B1: OrderDate | C1: CustomerID | D1: RegionID | E1: CustomerName | F1: Segment | G1: RegionName | H1: OrderMonth | I1: DeliveryDays | J1: IsDelayed | K1: IsCancelled | L1: Total Revenue | M1: Column1 | N1: Over all profit margin
A2: 1 | B2: 45383 | C2: 390 | D2: 3 | E2: =IFERROR(INDEX(Customers!$B$2:$B$901,MATCH(C2,Customers!$A$2:$A$901,0)),"") -> Meera Krishnan | F2: =IFERROR(INDEX(Customers!$C$2:$C$901,MATCH(C2,Customers!$A$2:$A$901,0)),"") -> Consumer | G2: =IFERROR(INDEX(Regions!$B$2:$B$6,MATCH(D2,Regions!$A$2:$A$6,0)),"") -> East | H2: =TEXT(B2,"YYYY-MM") -> 2024-04 | I2: =IFERROR(INDEX(Delivery!$C$2:$C$3001,MATCH(A2,Delivery!$A$2:$A$3001,0))-INDEX(Delivery!$B$2:$B$3001,MATCH(A2,Delivery!$A$2:$A$3001,0)),"") -> 5 | J2: =IF(IFERROR(INDEX(Delivery!$D$2:$D$3001,MATCH(A2,Delivery!$A$2:$A$3001,0)),"")="Delayed","Yes","No") -> No | K2: =IF(IFERROR(INDEX(Delivery!$D$2:$D$3001,MATCH(A2,Delivery!$A$2:$A$3001,0)),"")="Cancelled","Yes","No") -> No | L2: =SUMIF(Sales!B:B,A2,Sales!H:H) -> 3794.7 | M2: =SUM(L:L) -> 5047627.2 | N2: =2333641.85/5047627.21 -> 0.46232452
A3: 2 | B3: 45383 | C3: 821 | D3: 5 | E3: =IFERROR(INDEX(Customers!$B$2:$B$901,MATCH(C3,Customers!$A$2:$A$901,0)),"") -> Pari Iyer | F3: =IFERROR(INDEX(Customers!$C$2:$C$901,MATCH(C3,Customers!$A$2:$A$901,0)),"") -> Consumer | G3: =IFERROR(INDEX(Regions!$B$2:$B$6,MATCH(D3,Regions!$A$2:$A$6,0)),"") -> Central | H3: =TEXT(B3,"YYYY-MM") -> 2024-04 | I3: =IFERROR(INDEX(Delivery!$C$2:$C$3001,MATCH(A3,Delivery!$A$2:$A$3001,0))-INDEX(Delivery!$B$2:$B$3001,MATCH(A3,Delivery!$A$2:$A$3001,0)),"") -> 5 | J3: =IF(IFERROR(INDEX(Delivery!$D$2:$D$3001,MATCH(A3,Delivery!$A$2:$A$3001,0)),"")="Delayed","Yes","No") -> No | K3: =IF(IFERROR(INDEX(Delivery!$D$2:$D$3001,MATCH(A3,Delivery!$A$2:$A$3001,0)),"")="Cancelled","Yes","No") -> No | L3: =SUMIF(Sales!B:B,A3,Sales!H:H) -> 3429.16
A4: 3 | B4: 45383 | C4: 776 | D4: 3 | E4: =IFERROR(INDEX(Customers!$B$2:$B$901,MATCH(C4,Customers!$A$2:$A$901,0)),"") -> Saanvi Das | F4: =IFERROR(INDEX(Customers!$C$2:$C$901,MATCH(C4,Customers!$A$2:$A$901,0)),"") -> SMB | G4: =IFERROR(INDEX(Regions!$B$2:$B$6,MATCH(D4,Regions!$A$2:$A$6,0)),"") -> East | H4: =TEXT(B4,"YYYY-MM") -> 2024-04 | I4: =IFERROR(INDEX(Delivery!$C$2:$C$3001,MATCH(A4,Delivery!$A$2:$A$3001,0))-INDEX(Delivery!$B$2:$B$3001,MATCH(A4,Delivery!$A$2:$A$3001,0)),"") -> 6 | J4: =IF(IFERROR(INDEX(Delivery!$D$2:$D$3001,MATCH(A4,Delivery!$A$2:$A$3001,0)),"")="Delayed","Yes","No") -> No | K4: =IF(IFERROR(INDEX(Delivery!$D$2:$D$3001,MATCH(A4,Delivery!$A$2:$A$3001,0)),"")="Cancelled","Yes","No") -> No | L4: =SUMIF(Sales!B:B,A4,Sales!H:H) -> 1458.83
A5: 4 | B5: 45383 | C5: 260 | D5: 3 | E5: =IFERROR(INDEX(Customers!$B$2:$B$901,MATCH(C5,Customers!$A$2:$A$901,0)),"") -> Lakshmi Shetty | F5: =IFERROR(INDEX(Customers!$C$2:$C$901,MATCH(C5,Customers!$A$2:$A$901,0)),"") -> Consumer | G5: =IFERROR(INDEX(Regions!$B$2:$B$6,MATCH(D5,Regions!$A$2:$A$6,0)),"") -> East | H5: =TEXT(B5,"YYYY-MM") -> 2024-04 | I5: =IFERROR(INDEX(Delivery!$C$2:$C$3001,MATCH(A5,Delivery!$A$2:$A$3001,0))-INDEX(Delivery!$B$2:$B$3001,MATCH(A5,Delivery!$A$2:$A$3001,0)),"") -> 10 | J5: =IF(IFERROR(INDEX(Delivery!$D$2:$D$3001,MATCH(A5,Delivery!$A$2:$A$3001,0)),"")="Delayed","Yes","No") -> Yes | K5: =IF(IFERROR(INDEX(Delivery!$D$2:$D$3001,MATCH(A5,Delivery!$A$2:$A$3001,0)),"")="Cancelled","Yes","No") -> No | L5: =SUMIF(Sales!B:B,A5,Sales!H:H) -> 705.26
A6: 5 | B6: 45384 | C6: 889 | D6: 5 | E6: =IFERROR(INDEX(Customers!$B$2:$B$901,MATCH(C6,Customers!$A$2:$A$901,0)),"") -> Krishna Kapoor | F6: =IFERROR(INDEX(Customers!$C$2:$C$901,MATCH(C6,Customers!$A$2:$A$901,0)),"") -> SMB | G6: =IFERROR(INDEX(Regions!$B$2:$B$6,MATCH(D6,Regions!$A$2:$A$6,0)),"") -> Central | H6: =TEXT(B6,"YYYY-MM") -> 2024-04 | I6: =IFERROR(INDEX(Delivery!$C$2:$C$3001,MATCH(A6,Delivery!$A$2:$A$3001,0))-INDEX(Delivery!$B$2:$B$3001,MATCH(A6,Delivery!$A$2:$A$3001,0)),"") -> 2 | J6: =IF(IFERROR(INDEX(Delivery!$D$2:$D$3001,MATCH(A6,Delivery!$A$2:$A$3001,0)),"")="Delayed","Yes","No") -> No | K6: =IF(IFERROR(INDEX(Delivery!$D$2:$D$3001,MATCH(A6,Delivery!$A$2:$A$3001,0)),"")="Cancelled","Yes","No") -> No | L6: =SUMIF(Sales!B:B,A6,Sales!H:H) -> 741.85
A7: 6 | B7: 45384 | C7: 56 | D7: 2 | E7: =IFERROR(INDEX(Customers!$B$2:$B$901,MATCH(C7,Customers!$A$2:$A$901,0)),"") -> Aadhya Bose | F7: =IFERROR(INDEX(Customers!$C$2:$C$901,MATCH(C7,Customers!$A$2:$A$901,0)),"") -> Consumer | G7: =IFERROR(INDEX(Regions!$B$2:$B$6,MATCH(D7,Regions!$A$2:$A$6,0)),"") -> South | H7: =TEXT(B7,"YYYY-MM") -> 2024-04 | I7: =IFERROR(INDEX(Delivery!$C$2:$C$3001,MATCH(A7,Delivery!$A$2:$A$3001,0))-INDEX(Delivery!$B$2:$B$3001,MATCH(A7,Delivery!$A$2:$A$3001,0)),"") -> -45385 | J7: =IF(IFERROR(INDEX(Delivery!$D$2:$D$3001,MATCH(A7,Delivery!$A$2:$A$3001,0)),"")="Delayed","Yes","No") -> No | K7: =IF(IFERROR(INDEX(Delivery!$D$2:$D$3001,MATCH(A7,Delivery!$A$2:$A$3001,0)),"")="Cancelled","Yes","No") -> Yes | L7: =SUMIF(Sales!B:B,A7,Sales!H:H) -> 2213.32
A8: 7 | B8: 45384 | C8: 56 | D8: 2 | E8: =IFERROR(INDEX(Customers!$B$2:$B$901,MATCH(C8,Customers!$A$2:$A$901,0)),"") -> Aadhya Bose | F8: =IFERROR(INDEX(Customers!$C$2:$C$901,MATCH(C8,Customers!$A$2:$A$901,0)),"") -> Consumer | G8: =IFERROR(INDEX(Regions!$B$2:$B$6,MATCH(D8,Regions!$A$2:$A$6,0)),"") -> South | H8: =TEXT(B8,"YYYY-MM") -> 2024-04 | I8: =IFERROR(INDEX(Delivery!$C$2:$C$3001,MATCH(A8,Delivery!$A$2:$A$3001,0))-INDEX(Delivery!$B$2:$B$3001,MATCH(A8,Delivery!$A$2:$A$3001,0)),"") -> 3 | J8: =IF(IFERROR(INDEX(Delivery!$D$2:$D$3001,MATCH(A8,Delivery!$A$2:$A$3001,0)),"")="Delayed","Yes","No") -> No | K8: =IF(IFERROR(INDEX(Delivery!$D$2:$D$3001,MATCH(A8,Delivery!$A$2:$A$3001,0)),"")="Cancelled","Yes","No") -> No | L8: =SUMIF(Sales!B:B,A8,Sales!H:H) -> 2564.61
A9: 8 | B9: 45385 | C9: 430 | D9: 4 | E9: =IFERROR(INDEX(Customers!$B$2:$B$901,MATCH(C9,Customers!$A$2:$A$901,0)),"") -> Vihaan Chatterjee | F9: =IFERROR(INDEX(Customers!$C$2:$C$901,MATCH(C9,Customers!$A$2:$A$901,0)),"") -> Consumer | G9: =IFERROR(INDEX(Regions!$B$2:$B$6,MATCH(D9,Regions!$A$2:$A$6,0)),"") -> West | H9: =TEXT(B9,"YYYY-MM") -> 2024-04 | I9: =IFERROR(INDEX(Delivery!$C$2:$C$3001,MATCH(A9,Delivery!$A$2:$A$3001,0))-INDEX(Delivery!$B$2:$B$3001,MATCH(A9,Delivery!$A$2:$A$3001,0)),"") -> 2 | J9: =IF(IFERROR(INDEX(Delivery!$D$2:$D$3001,MATCH(A9,Delivery!$A$2:$A$3001,0)),"")="Delayed","Yes","No") -> No | K9: =IF(IFERROR(INDEX(Delivery!$D$2:$D$3001,MATCH(A9,Delivery!$A$2:$A$3001,0)),"")="Cancelled","Yes","No") -> No | L9: =SUMIF(Sales!B:B,A9,Sales!H:H) -> 3021.65
A10: 9 | B10: 45385 | C10: 281 | D10: 3 | E10: =IFERROR(INDEX(Customers!$B$2:$B$901,MATCH(C10,Customers!$A$2:$A$901,0)),"") -> Meera Bose | F10: =IFERROR(INDEX(Customers!$C$2:$C$901,MATCH(C10,Customers!$A$2:$A$901,0)),"") -> Consumer | G10: =IFERROR(INDEX(Regions!$B$2:$B$6,MATCH(D10,Regions!$A$2:$A$6,0)),"") -> East | H10: =TEXT(B10,"YYYY-MM") -> 2024-04 | I10: =IFERROR(INDEX(Delivery!$C$2:$C$3001,MATCH(A10,Delivery!$A$2:$A$3001,0))-INDEX(Delivery!$B$2:$B$3001,MATCH(A10,Delivery!$A$2:$A$3001,0)),"") -> 6 | J10: =IF(IFERROR(INDEX(Delivery!$D$2:$D$3001,MATCH(A10,Delivery!$A$2:$A$3001,0)),"")="Delayed","Yes","No") -> No | K10: =IF(IFERROR(INDEX(Delivery!$D$2:$D$3001,MATCH(A10,Delivery!$A$2:$A$3001,0)),"")="Cancelled","Yes","No") -> No | L10: =SUMIF(Sales!B:B,A10,Sales!H:H) -> 3197.34
A11: 10 | B11: 45385 | C11: 788 | D11: 1 | E11: =IFERROR(INDEX(Customers!$B$2:$B$901,MATCH(C11,Customers!$A$2:$A$901,0)),"") -> Reyansh Sharma | F11: =IFERROR(INDEX(Customers!$C$2:$C$901,MATCH(C11,Customers!$A$2:$A$901,0)),"") -> Consumer | G11: =IFERROR(INDEX(Regions!$B$2:$B$6,MATCH(D11,Regions!$A$2:$A$6,0)),"") -> North | H11: =TEXT(B11,"YYYY-MM") -> 2024-04 | I11: =IFERROR(INDEX(Delivery!$C$2:$C$3001,MATCH(A11,Delivery!$A$2:$A$3001,0))-INDEX(Delivery!$B$2:$B$3001,MATCH(A11,Delivery!$A$2:$A$3001,0)),"") -> 4 | J11: =IF(IFERROR(INDEX(Delivery!$D$2:$D$3001,MATCH(A11,Delivery!$A$2:$A$3001,0)),"")="Delayed","Yes","No") -> No | K11: =IF(IFERROR(INDEX(Delivery!$D$2:$D$3001,MATCH(A11,Delivery!$A$2:$A$3001,0)),"")="Cancelled","Yes","No") -> No | L11: =SUMIF(Sales!B:B,A11,Sales!H:H) -> 390.4
A12: 11 | B12: 45385 | C12: 24 | D12: 2 | E12: =IFERROR(INDEX(Customers!$B$2:$B$901,MATCH(C12,Customers!$A$2:$A$901,0)),"") -> Arjun Menon | F12: =IFERROR(INDEX(Customers!$C$2:$C$901,MATCH(C12,Customers!$A$2:$A$901,0)),"") -> Consumer | G12: =IFERROR(INDEX(Regions!$B$2:$B$6,MATCH(D12,Regions!$A$2:$A$6,0)),"") -> South | H12: =TEXT(B12,"YYYY-MM") -> 2024-04 | I12: =IFERROR(INDEX(Delivery!$C$2:$C$3001,MATCH(A12,Delivery!$A$2:$A$3001,0))-INDEX(Delivery!$B$2:$B$3001,MATCH(A12,Delivery!$A$2:$A$3001,0)),"") -> 2 | J12: =IF(IFERROR(INDEX(Delivery!$D$2:$D$3001,MATCH(A12,Delivery!$A$2:$A$3001,0)),"")="Delayed","Yes","No") -> No | K12: =IF(IFERROR(INDEX(Delivery!$D$2:$D$3001,MATCH(A12,Delivery!$A$2:$A$3001,0)),"")="Cancelled","Yes","No") -> No | L12: =SUMIF(Sales!B:B,A12,Sales!H:H) -> 175.69
A13: 12 | B13: 45385 | C13: 809 | D13: 5 | E13: =IFERROR(INDEX(Customers!$B$2:$B$901,MATCH(C13,Customers!$A$2:$A$901,0)),"") -> Suresh Joshi | F13: =IFERROR(INDEX(Customers!$C$2:$C$901,MATCH(C13,Customers!$A$2:$A$901,0)),"") -> Consumer | G13: =IFERROR(INDEX(Regions!$B$2:$B$6,MATCH(D13,Regions!$A$2:$A$6,0)),"") -> Central | H13: =TEXT(B13,"YYYY-MM") -> 2024-04 | I13: =IFERROR(INDEX(Delivery!$C$2:$C$3001,MATCH(A13,Delivery!$A$2:$A$3001,0))-INDEX(Delivery!$B$2:$B$3001,MATCH(A13,Delivery!$A$2:$A$3001,0)),"") -> 2 | J13: =IF(IFERROR(INDEX(Delivery!$D$2:$D$3001,MATCH(A13,Delivery!$A$2:$A$3001,0)),"")="Delayed","Yes","No") -> No | K13: =IF(IFERROR(INDEX(Delivery!$D$2:$D$3001,MATCH(A13,Delivery!$A$2:$A$3001,0)),"")="Cancelled","Yes","No") -> No | L13: =SUMIF(Sales!B:B,A13,Sales!H:H) -> 1575.6
A14: 13 | B14: 45385 | C14: 242 | D14: 4 | E14: =IFERROR(INDEX(Customers!$B$2:$B$901,MATCH(C14,Customers!$A$2:$A$901,0)),"") -> Aadhya Bose | F14: =IFERROR(INDEX(Customers!$C$2:$C$901,MATCH(C14,Customers!$A$2:$A$901,0)),"") -> Consumer | G14: =IFERROR(INDEX(Regions!$B$2:$B$6,MATCH(D14,Regions!$A$2:$A$6,0)),"") -> West | H14: =TEXT(B14,"YYYY-MM") -> 2024-04 | I14: =IFERROR(INDEX(Delivery!$C$2:$C$3001,MATCH(A14,Delivery!$A$2:$A$3001,0))-INDEX(Delivery!$B$2:$B$3001,MATCH(A14,Delivery!$A$2:$A$3001,0)),"") -> 2 | J14: =IF(IFERROR(INDEX(Delivery!$D$2:$D$3001,MATCH(A14,Delivery!$A$2:$A$3001,0)),"")="Delayed","Yes","No") -> No | K14: =IF(IFERROR(INDEX(Delivery!$D$2:$D$3001,MATCH(A14,Delivery!$A$2:$A$3001,0)),"")="Cancelled","Yes","No") -> No | L14: =SUMIF(Sales!B:B,A14,Sales!H:H) -> 175.69
... A3001: 3000 | B3001: 45921 | C3001: 661 | D3001: 5 | E3001: =IFERROR(INDEX(Customers!$B$2:$B$901,MATCH(C3001,Customers!$A$2:$A$901,0)),"") -> Kiara Pillai | F3001: =IFERROR(INDEX(Customers!$C$2:$C$901,MATCH(C3001,Customers!$A$2:$A$901,0)),"") -> Consumer | G3001: =IFERROR(INDEX(Regions!$B$2:$B$6,MATCH(D3001,Regions!$A$2:$A$6,0)),"") -> Central | H3001: =TEXT(B3001,"YYYY-MM") -> 2025-09 | I3001: =IFERROR(INDEX(Delivery!$C$2:$C$3001,MATCH(A3001,Delivery!$A$2:$A$3001,0))-INDEX(Delivery!$B$2:$B$3001,MATCH(A3001,Delivery!$A$2:$A$3001,0)),"") -> 3 | J3001: =IF(IFERROR(INDEX(Delivery!$D$2:$D$3001,MATCH(A3001,Delivery!$A$2:$A$3001,0)),"")="Delayed","Yes","No") -> No | K3001: =IF(IFERROR(INDEX(Delivery!$D$2:$D$3001,MATCH(A3001,Delivery!$A$2:$A$3001,0)),"")="Cancelled","Yes","No") -> No | L3001: =SUMIF(Sales!B:B,A3001,Sales!H:H) -> 889.52

Sheet Sheet4
A3: Sum of Profit
A4: 2333641.8

Sheet Sales
A1: OrderLineID | B1: OrderID | C1: ProductID | D1: Quantity | E1: UnitPrice | F1: DiscountPct | G1: CategoryID | H1: Cost | I1: Revenue | J1: TotalCost | K1: Profit | L1: ProfitMargin% | M1: IsReturned | N1: Column1
A2: 1 | B2: 1 | C2: 1049 | D2: 2 | E2: 3970.29 | F2: 0.1 | G2: =IFERROR(INDEX(Products!$C$2:$C$86,MATCH(C2,Products!$A$2:$A$86,0)),"") -> 5 | H2: =IFERROR(INDEX(Products!$D$2:$D$86,MATCH(C2,Products!$A$2:$A$86,0)),"") -> 2490.89 | I2: =D2*E2*(1-F2) -> 7146.522 | J2: =D2*H2 -> 4981.78 | K2: =I2-J2 -> 2164.742 | L2: =IFERROR(K2/I2,0) -> 0.30290846 | M2: =IF(COUNTIF(Returns!$B$2:$B$248,A2)>0,"Yes","No") -> No
A3: 2 | B3: 1 | C3: 1009 | D3: 1 | E3: 2129.15 | F3: 0 | G3: =IFERROR(INDEX(Products!$C$2:$C$86,MATCH(C3,Products!$A$2:$A$86,0)),"") -> 1 | H3: =IFERROR(INDEX(Products!$D$2:$D$86,MATCH(C3,Products!$A$2:$A$86,0)),"") -> 1303.81 | I3: =D3*E3*(1-F3) -> 2129.15 | J3: =D3*H3 -> 1303.81 | K3: =I3-J3 -> 825.34 | L3: =IFERROR(K3/I3,0) -> 0.38763826 | M3: =IF(COUNTIF(Returns!$B$2:$B$248,A3)>0,"Yes","No") -> Yes
A4: 3 | B4: 2 | C4: 1001 | D4: 1 | E4: 3826.19 | F4: 0.15 | G4: =IFERROR(INDEX(Products!$C$2:$C$86,MATCH(C4,Products!$A$2:$A$86,0)),"") -> 1 | H4: =IFERROR(INDEX(Products!$D$2:$D$86,MATCH(C4,Products!$A$2:$A$86,0)),"") -> 3021.65 | I4: =D4*E4*(1-F4) -> 3252.2615 | J4: =D4*H4 -> 3021.65 | K4: =I4-J4 -> 230.6115 | L4: =IFERROR(K4/I4,0) -> 0.070908044 | M4: =IF(COUNTIF(Returns!$B$2:$B$248,A4)>0,"Yes","No") -> No
A5: 4 | B5: 2 | C5: 1043 | D5: 1 | E5: 567.48 | F5: 0 | G5: =IFERROR(INDEX(Products!$C$2:$C$86,MATCH(C5,Products!$A$2:$A$86,0)),"") -> 4 | H5: =IFERROR(INDEX(Products!$D$2:$D$86,MATCH(C5,Products!$A$2:$A$86,0)),"") -> 407.51 | I5: =D5*E5*(1-F5) -> 567.48 | J5: =D5*H5 -> 407.51 | K5: =I5-J5 -> 159.97 | L5: =IFERROR(K5/I5,0) -> 0.2818954 | M5: =IF(COUNTIF(Returns!$B$2:$B$248,A5)>0,"Yes","No") -> No
A6: 5 | B6: 3 | C6: 1032 | D6: 1 | E6: 2472.72 | F6: 0 | G6: =IFERROR(INDEX(Products!$C$2:$C$86,MATCH(C6,Products!$A$2:$A$86,0)),"") -> 3 | H6: =IFERROR(INDEX(Products!$D$2:$D$86,MATCH(C6,Products!$A$2:$A$86,0)),"") -> 1458.83 | I6: =D6*E6*(1-F6) -> 2472.72 | J6: =D6*H6 -> 1458.83 | K6: =I6-J6 -> 1013.89 | L6: =IFERROR(K6/I6,0) -> 0.41003025 | M6: =IF(COUNTIF(Returns!$B$2:$B$248,A6)>0,"Yes","No") -> No
A7: 6 | B7: 4 | C7: 1061 | D7: 1 | E7: 1128.84 | F7: 0.25 | G7: =IFERROR(INDEX(Products!$C$2:$C$86,MATCH(C7,Products!$A$2:$A$86,0)),"") -> 6 | H7: =IFERROR(INDEX(Products!$D$2:$D$86,MATCH(C7,Products!$A$2:$A$86,0)),"") -> 705.26 | I7: =D7*E7*(1-F7) -> 846.63 | J7: =D7*H7 -> 705.26 | K7: =I7-J7 -> 141.37 | L7: =IFERROR(K7/I7,0) -> 0.16697967 | M7: =IF(COUNTIF(Returns!$B$2:$B$248,A7)>0,"Yes","No") -> No
A8: 7 | B8: 5 | C8: 1016 | D8: 1 | E8: 1279.19 | F8: 0 | G8: =IFERROR(INDEX(Products!$C$2:$C$86,MATCH(C8,Products!$A$2:$A$86,0)),"") -> 2 | H8: =IFERROR(INDEX(Products!$D$2:$D$86,MATCH(C8,Products!$A$2:$A$86,0)),"") -> 741.85 | I8: =D8*E8*(1-F8) -> 1279.19 | J8: =D8*H8 -> 741.85 | K8: =I8-J8 -> 537.34 | L8: =IFERROR(K8/I8,0) -> 0.4200627 | M8: =IF(COUNTIF(Returns!$B$2:$B$248,A8)>0,"Yes","No") -> No
A9: 8 | B9: 6 | C9: 1067 | D9: 1 | E9: 4128.99 | F9: 0.1 | G9: =IFERROR(INDEX(Products!$C$2:$C$86,MATCH(C9,Products!$A$2:$A$86,0)),"") -> 7 | H9: =IFERROR(INDEX(Products!$D$2:$D$86,MATCH(C9,Products!$A$2:$A$86,0)),"") -> 2213.32 | I9: =D9*E9*(1-F9) -> 3716.091 | J9: =D9*H9 -> 2213.32 | K9: =I9-J9 -> 1502.771 | L9: =IFERROR(K9/I9,0) -> 0.40439564 | M9: =IF(COUNTIF(Returns!$B$2:$B$248,A9)>0,"Yes","No") -> No
A10: 9 | B10: 7 | C10: 1067 | D10: 2 | E10: 4128.99 | F10: 0.3 | G10: =IFERROR(INDEX(Products!$C$2:$C$86,MATCH(C10,Products!$A$2:$A$86,0)),"") -> 7 | H10: =IFERROR(INDEX(Products!$D$2:$D$86,MATCH(C10,Products!$A$2:$A$86,0)),"") -> 2213.32 | I10: =D10*E10*(1-F10) -> 5780.586 | J10: =D10*H10 -> 4426.64 | K10: =I10-J10 -> 1353.946 | L10: =IFERROR(K10/I10,0) -> 0.23422297 | M10: =IF(COUNTIF(Returns!$B$2:$B$248,A10)>0,"Yes","No") -> No
A11: 10 | B11: 7 | C11: 1068 | D11: 1 | E11: 550.08 | F11: 0 | G11: =IFERROR(INDEX(Products!$C$2:$C$86,MATCH(C11,Products!$A$2:$A$86,0)),"") -> 7 | H11: =IFERROR(INDEX(Products!$D$2:$D$86,MATCH(C11,Products!$A$2:$A$86,0)),"") -> 351.29 | I11: =D11*E11*(1-F11) -> 550.08 | J11: =D11*H11 -> 351.29 | K11: =I11-J11 -> 198.79 | L11: =IFERROR(K11/I11,0) -> 0.3613838 | M11: =IF(COUNTIF(Returns!$B$2:$B$248,A11)>0,"Yes","No") -> No
A12: 11 | B12: 8 | C12: 1001 | D12: 1 | E12: 3826.19 | F12: 0.25 | G12: =IFERROR(INDEX(Products!$C$2:$C$86,MATCH(C12,Products!$A$2:$A$86,0)),"") -> 1 | H12: =IFERROR(INDEX(Products!$D$2:$D$86,MATCH(C12,Products!$A$2:$A$86,0)),"") -> 3021.65 | I12: =D12*E12*(1-F12) -> 2869.6425 | J12: =D12*H12 -> 3021.65 | K12: =I12-J12 -> -152.0075 | L12: =IFERROR(K12/I12,0) -> -0.052970884 | M12: =IF(COUNTIF(Returns!$B$2:$B$248,A12)>0,"Yes","No") -> No
A13: 12 | B13: 9 | C13: 1085 | D13: 1 | E13: 234.72 | F13: 0.05 | G13: =IFERROR(INDEX(Products!$C$2:$C$86,MATCH(C13,Products!$A$2:$A$86,0)),"") -> 8 | H13: =IFERROR(INDEX(Products!$D$2:$D$86,MATCH(C13,Products!$A$2:$A$86,0)),"") -> 175.69 | I13: =D13*E13*(1-F13) -> 222.984 | J13: =D13*H13 -> 175.69 | K13: =I13-J13 -> 47.294 | L13: =IFERROR(K13/I13,0) -> 0.21209594 | M13: =IF(COUNTIF(Returns!$B$2:$B$248,A13)>0,"Yes","No") -> No
... A4584: 4583 | B4584: 3000 | C4584: 1061 | D4584: 2 | E4584: 1128.84 | F4584: 0 | G4584: =IFERROR(INDEX(Products!$C$2:$C$86,MATCH(C4584,Products!$A$2:$A$86,0)),"") -> 6 | H4584: =IFERROR(INDEX(Products!$D$2:$D$86,MATCH(C4584,Products!$A$2:$A$86,0)),"") -> 705.26 | I4584: =D4584*E4584*(1-F4584) -> 2257.68 | J4584: =D4584*H4584 -> 1410.52 | K4584: =I4584-J4584 -> 847.16 | L4584: =IFERROR(K4584/I4584,0) -> 0.37523475 | M4584: =IF(COUNTIF(Returns!$B$2:$B$248,A4584)>0,"Yes","No") -> No

Sheet Delivery
A1: OrderID | B1: ShipDate | C1: DeliveryDate | D1: DeliveryStatus
A2: 1 | B2: 45383 | C2: 45388 | D2: Delivered
A3: 2 | B3: 45385 | C3: 45390 | D3: Delivered
A4: 3 | B4: 45383 | C4: 45389 | D4: Delivered
A5: 4 | B5: 45383 | C5: 45393 | D5: Delayed
A6: 5 | B6: 45384 | C6: 45386 | D6: Delivered
A7: 6 | B7: 45385 | D7: Cancelled
A8: 7 | B8: 45385 | C8: 45388 | D8: Delivered
A9: 8 | B9: 45385 | C9: 45387 | D9: Delivered
A10: 9 | B10: 45386 | C10: 45392 | D10: Delivered
A11: 10 | B11: 45386 | C11: 45390 | D11: Delivered
A12: 11 | B12: 45387 | C12: 45389 | D12: Delivered
A13: 12 | B13: 45387 | C13: 45389 | D13: Delivered
A14: 13 | B14: 45385 | C14: 45387 | D14: Delivered
A15: 14 | B15: 45386 | C15: 45389 | D15: Delivered
A16: 15 | B16: 45388 | C16: 45393 | D16: Delivered
A17: 16 | B17: 45387 | C17: 45390 | D17: Delivered
A18: 17 | B18: 45388 | C18: 45393 | D18: Delivered
A19: 18 | B19: 45387 | C19: 45390 | D19: Delivered
A20: 19 | B20: 45387 | D20: Cancelled
A21: 20 | B21: 45389 | C21: 45391 | D21: Delivered
A22: 21 | B22: 45389 | C22: 45395 | D22: Delivered
A23: 22 | B23: 45388 | C23: 45392 | D23: Delivered
A24: 23 | B24: 45387 | C24: 45396 | D24: Delayed
A25: 24 | B25: 45388 | C25: 45393 | D25: Delivered
A26: 25 | B26: 45389 | C26: 45393 | D26: Delivered
A27: 26 | B27: 45388 | C27: 45392 | D27: Delivered
A28: 27 | B28: 45388 | C28: 45391 | D28: Delivered
A29: 28 | B29: 45390 | C29: 45392 | D29: Delivered
A30: 29 | B30: 45389 | C30: 45395 | D30: Delivered
A31: 30 | B31: 45390 | C31: 45397 | D31: Delayed
A32: 31 | B32: 45391 | D32: Cancelled
A33: 32 | B33: 45390 | C33: 45400 | D33: Delayed
A34: 33 | B34: 45389 | C34: 45392 | D34: Delivered
A35: 34 | B35: 45391 | C35: 45395 | D35: Delivered
A36: 35 | B36: 45390 | D36: Cancelled
A37: 36 | B37: 45390 | C37: 45392 | D37: Delivered
A38: 37 | B38: 45390 | C38: 45393 | D38: Delivered
A39: 38 | B39: 45392 | C39: 45395 | D39: Delivered
A40: 39 | B40: 45394 | C40: 45400 | D40: Delivered
...

Sheet Returns
A1: ReturnID | B1: OrderLineID | C1: ReturnDate | D1: ReturnReason
A2: 1 | B2: 2 | C2: 45398 | D2: Wrong Item Received
A3: 2 | B3: 16 | C3: 45400 | D3: Wrong Item Received
A4: 3 | B4: 29 | C4: 45398 | D4: Wrong Item Received
A5: 4 | B5: 30 | C5: 45400 | D5: Wrong Item Received
A6: 5 | B6: 59 | C6: 45401 | D6: Size/Fit Issue
A7: 6 | B7: 69 | C7: 45402 | D7: Defective/Damaged
A8: 7 | B8: 74 | C8: 45401 | D8: Not as Described
A9: 8 | B9: 77 | C9: 45407 | D9: Not as Described
A10: 9 | B10: 86 | C10: 45417 | D10: Defective/Damaged
A11: 10 | B11: 95 | C11: 45415 | D11: Defective/Damaged
A12: 11 | B12: 108 | C12: 45406 | D12: Not as Described
A13: 12 | B13: 143 | C13: 45413 | D13: Wrong Item Received
... A248: 247 | B248: 4526 | C248: 45932 | D248: Defective/Damaged

Sheet Metrics
A1: Executive KPI Summary
A3: Total Revenue | B3: =SUM(Sales!I2:I4584) -> 8680119.4
A4: Total Profit | B4: =SUM(Sales!K2:K4584) -> 2333641.8
A5: Profit Margin % | B5: =B4/B3 -> 0.26884905
A6: Total Orders | B6: =COUNTA(Orders!A2:A3001) -> 3000
A7: Total Customers | B7: =COUNTA(Customers!A2:A901) -> 900
A8: Average Order Value (AOV) | B8: =B3/B6 -> 2893.3731
A9: Total Returns | B9: =COUNTA(Returns!A2:A248) -> 247
A10: Total Order Lines | B10: =COUNTA(Sales!A2:A4584) -> 4583
A11: Return Rate | B11: =B9/B10 -> 0.053894829
A13: All figures are live formulas pulling from Sales, Orders, Customers, and Return sheets.

Sheet Sheet1
A3: Total Revenue | C3: Total Profit | E3: Profit Margin
A4: =Metrics!B3 -> 8680119.4 | C4: =Metrics!B4 -> 2333641.8 | E4: =Metrics!B5 -> 0.26884905
A6: Total Orders | C6: Total Customers | E6: AOV
A7: =Metrics!B6 -> 3000 | C7: =Metrics!B7 -> 900 | E7: =Metrics!B8 -> 2893.3731
A9: Total Returns | C9: Total Order Lines | E9: Return Rate
A10: =Metrics!B9 -> 247 | C10: =Metrics!B10 -> 4583 | E10: =Metrics!B11 -> 0.053894829

Sheet README
A1: E-commerce BI Dashboard — Stage 1 Dataset
A3: Coverage | B3: 18 months of order data: Apr 2024 – Sep 2025
A4: Orders | B4: 3,000 orders / 4,583 order lines
A5: Customers | B5: 900 customers across 3 segments (Consumer, Corporate, SMB) and 5 regions
A6: Products | B6: 85 products across 8 categories
A7: Returns | B7: 247 returns (~5.4% of order lines) — rates vary by category (Apparel & Electronics highest)
A8: Delivery | B8: Each order has a ship date, delivery date, and status (Delivered / Delayed / Cancelled)
A9: Design pattern | B9: Relational: tables link via ID columns (CustomerID, ProductID, RegionID, CategoryID, OrderID, OrderLineID) — mirrors a real e-commerce database
A10: Note on realism | B10: Data is synthetically generated with seasonality (festive spike in Oct–Nov), a mild growth trend, and Pareto-style product popularity, so KPIs and trends behave like a real business dataset.
A12: Next stage | B12: Added calculated columns and metrics such as Total Revenue, Profit, Profit Margin, Delivery Days, Returns, and Order-related measures using Excel formulas including XLOOKUP, SUMIFS, SUM, IF, and COUNT/COUNTA. These calculations were used to connect and analyze data across the Orders, Sales, Products, Customers, Region, Delivery, and Returns tables.
A13: Table Relationships
A14: Orders.CustomerID -> Customers.CustomerID
A15: Orders.RegionID -> Regions.RegionID
A16: Customers.RegionID -> Regions.RegionID
A17: Sales.OrderID -> Orders.OrderID
A18: Sales.ProductID -> Products.ProductID
A19: Products.CategoryID -> Categories.CategoryID
A20: Delivery.OrderID -> Orders.OrderID
A21: Returns.OrderLineID -> Sales.OrderLineID
